2025-06-19 13:50:04,585 - TeleBot - ERROR - Infinity polling exception: name 'start_time' is not defined
2025-06-19 13:50:04,589 - TeleBot - ERROR - Exception traceback:
Traceback (most recent call last):
  File "/home/teacher/.local/lib/python3.8/site-packages/telebot/__init__.py", line 1110, in infinity_polling
    self.polling(non_stop=True, timeout=timeout, long_polling_timeout=long_polling_timeout,
  File "/home/teacher/.local/lib/python3.8/site-packages/telebot/__init__.py", line 1198, in polling
    self.__threaded_polling(non_stop=non_stop, interval=interval, timeout=timeout, long_polling_timeout=long_polling_timeout,
  File "/home/teacher/.local/lib/python3.8/site-packages/telebot/__init__.py", line 1273, in __threaded_polling
    raise e
  File "/home/teacher/.local/lib/python3.8/site-packages/telebot/__init__.py", line 1235, in __threaded_polling
    self.worker_pool.raise_exceptions()
  File "/home/teacher/.local/lib/python3.8/site-packages/telebot/util.py", line 150, in raise_exceptions
    raise self.exception_info
  File "/home/teacher/.local/lib/python3.8/site-packages/telebot/util.py", line 93, in run
    task(*args, **kwargs)
  File "SRS.py", line 229, in process_start_time
    if not validate_time(start_time):
NameError: name 'start_time' is not defined

2025-06-19 13:56:05,836 - TeleBot - ERROR - Infinity polling: polling exited
2025-06-19 13:56:05,836 - TeleBot - ERROR - Break infinity polling
2025-06-19 14:00:37,397 - TeleBot - ERROR - Infinity polling: polling exited
2025-06-19 14:00:37,397 - TeleBot - ERROR - Break infinity polling
2025-06-19 14:08:18,359 - TeleBot - ERROR - Infinity polling: polling exited
2025-06-19 14:08:18,360 - TeleBot - ERROR - Break infinity polling
